[Fri Mar 20 22:04:35.828193 2020] [wsgi:error] [pid 25932:tid 140186250524416] [remote 186.137.65.209:36358] Invalid HTTP_HOST header: '67.205.157.216'. You may need to add '67.205.157.216' to ALLOWED_HOSTS.
[Fri Mar 20 22:04:35.858381 2020] [wsgi:error] [pid 25932:tid 140186250524416] [remote 186.137.65.209:36358] Bad Request: /v1/user/login/
[Fri Mar 20 22:04:38.165130 2020] [wsgi:error] [pid 25932:tid 140186284095232] [remote 186.137.65.209:36424] Invalid HTTP_HOST header: '67.205.157.216'. You may need to add '67.205.157.216' to ALLOWED_HOSTS.
[Fri Mar 20 22:04:38.197966 2020] [wsgi:error] [pid 25932:tid 140186284095232] [remote 186.137.65.209:36424] Bad Request: /v1/user/login/
Exception ignored in: <bound method BaseEventLoop.__del__ of <_UnixSelectorEventLoop running=False closed=False debug=False>>
Traceback (most recent call last):
  File "/usr/lib/python3.6/asyncio/base_events.py", line 526, in __del__
NameError: name 'ResourceWarning' is not defined
[Fri Mar 20 22:06:51.377591 2020] [wsgi:error] [pid 26055:tid 140093554390784] [remote 186.137.65.209:40696] Invalid HTTP_HOST header: '67.205.157.216'. You may need to add '67.205.157.216' to ALLOWED_HOSTS.
[Fri Mar 20 22:06:51.409040 2020] [wsgi:error] [pid 26055:tid 140093554390784] [remote 186.137.65.209:40696] Bad Request: /v1/user/login/
Exception ignored in: <bound method BaseEventLoop.__del__ of <_UnixSelectorEventLoop running=False closed=False debug=False>>
Traceback (most recent call last):
  File "/usr/lib/python3.6/asyncio/base_events.py", line 526, in __del__
NameError: name 'ResourceWarning' is not defined
[Fri Mar 20 22:07:23.852996 2020] [wsgi:error] [pid 26169:tid 139725683214080] [remote 186.137.65.209:41724] ingreso a login
[Fri Mar 20 22:07:23.853229 2020] [wsgi:error] [pid 26169:tid 139725683214080] [remote 186.137.65.209:41724] datos envidos:{'username': 'admin', 'password': 'aqswdefr'}
[Fri Mar 20 22:07:23.970930 2020] [wsgi:error] [pid 26169:tid 139725683214080] [remote 186.137.65.209:41724] Bad Request: /v1/user/login/
[Fri Mar 20 22:09:23.920371 2020] [wsgi:error] [pid 26169:tid 139725683214080] [remote 186.137.65.209:45640] Not Found: /v2
Exception ignored in: <bound method BaseEventLoop.__del__ of <_UnixSelectorEventLoop running=False closed=False debug=False>>
Traceback (most recent call last):
  File "/usr/lib/python3.6/asyncio/base_events.py", line 526, in __del__
NameError: name 'ResourceWarning' is not defined
[Fri Mar 20 22:11:47.435332 2020] [wsgi:error] [pid 26320:tid 139728274646784] [remote 186.137.65.209:50272] Not Found: /favicon.ico
[Fri Mar 20 22:12:58.126664 2020] [wsgi:error] [pid 26320:tid 139728274646784] [remote 186.137.65.209:52608] ingreso a login
[Fri Mar 20 22:12:58.126906 2020] [wsgi:error] [pid 26320:tid 139728274646784] [remote 186.137.65.209:52608] datos envidos:{'username': 'admin', 'password': 'aqswdefr'}
[Fri Mar 20 22:20:58.627787 2020] [wsgi:error] [pid 26320:tid 139728274646784] [remote 186.137.65.209:39812] Bad Request: /v1/api-token-auth/
[Fri Mar 20 22:21:23.812593 2020] [wsgi:error] [pid 26320:tid 139728274646784] [remote 186.137.65.209:40618] Bad Request: /v1/api-token-auth/
[Fri Mar 20 22:30:38.328041 2020] [wsgi:error] [pid 26320:tid 139728274646784] [remote 186.137.65.209:59268] Bad Request: /v1/api-token-auth/
[Fri Mar 20 22:30:44.593395 2020] [wsgi:error] [pid 26320:tid 139728241075968] [remote 186.137.65.209:59276] Bad Request: /v1/api-token-auth/
[Fri Mar 20 22:31:08.179041 2020] [wsgi:error] [pid 26320:tid 139728241075968] [remote 186.137.65.209:59282] Bad Request: /v1/api-token-auth/
[Fri Mar 20 22:32:40.710615 2020] [wsgi:error] [pid 26320:tid 139728274646784] [remote 186.137.65.209:59304] Bad Request: /v1/api-token-auth/
[Fri Mar 20 22:33:09.888332 2020] [wsgi:error] [pid 26320:tid 139728241075968] [remote 186.137.65.209:59310] Bad Request: /v1/api-token-auth/
[Fri Mar 20 22:35:06.933702 2020] [wsgi:error] [pid 26320:tid 139728241075968] [remote 186.137.65.209:59334] Bad Request: /v1/api-token-auth/
[Fri Mar 20 22:39:15.855243 2020] [wsgi:error] [pid 26320:tid 139728274646784] [remote 186.137.65.209:59388] Bad Request: /v1/api-token-auth/
